Workbook
Name GRAND: 'Continuation Sheet'!#REF!
Name Print_Area_MI: 'Continuation Sheet'!$B$13:$K$44
Name Print_Area_MI: Application!$A$1:$N$55
Name Print_Titles_MI: 'Continuation Sheet'!$1:$12
Name Print_Titles_MI: Application!$68:$375,Application!$B:$DE

Sheet Application
A1: APPLICATION FOR PAYMENT | J1: PAGE ONE OF | K1: 2 | N1: PAGES
A3: TO OWNER: | D3: PROJECT:
B5: Jay Terkiana | D5: Jay Immigration Lawyer Office
B7: 377 S Daniel Way,
B9: San Jose, CA 95128 | K9: Distribution to:
A11: FROM CONTRACTOR: | D11: SCOPE OF WORK: | H11: APPLICATION NO: | I11: 4 | K11: X | L11: OWNER
B13: Bains Developments Commercial | D13: Jay Immigration Lawyer Office | H13: APPLICATION DATE: | I13: 44837 | L13: ARCHITECT
B15: 980 Mission Ct. | H15: PAYMENT TERM: | I15: Due on receipt | L15: CONTRACTOR
B16: Fremont, CA 94539 | H16: JOB NO: | I16: 03011 | L16: FILE
A17: CONTRACT FOR:
A19: CONTRACTOR'S APPLICATION FOR PAYMENT | G19: The undersigned Contractor certifies that to the best of the Contractor's knowledge,
A20: Application is made for payment, as shown below, in connection with the Contract. | G20: information and belief the Work covered by this Application for Payment has been
A21: Continuation Sheet is attached. | G21: completed in accordance with the Contract Documents, that all amounts have been paid by
G22: the Contractor for Work for which previous Certificates for Payment were issued and
G23: payments received from the Owner, and that current payment shown herein is now due.
A25: 1. ORIGINAL CONTRACT SUM | D25: $ | E25: 781782
A26: 2. Net change by Change Orders | D26: $ | E26: =+D53 -> 54132 | G26: CONTRACTOR:
A27: 3. CONTRACT SUM TO DATE (Line 1 ± 2) $ | D27: $ | E27: =IF(SUM(E25,E26)=0,"",SUM(E25,E26)) -> 835914
A28: 4. TOTAL COMPLETED & STORED TO | D28: $ | E28: =+'Continuation Sheet'!H42 -> 518160.63
A29: DATE (Column G on G703) | G29: By: | H29: Vagish Kapila | K29: Date: | N29: =I13 -> 44837
A30: 5. RETAINAGE:
A31: a. | B31: 10 | C31: % of Completed Work $ | D31: =+'Continuation Sheet'!K42 -> 0 | G31: State of: | J31: County of:
B32: (Column D + E on G703) | G32: Subscribed and sworn to before me this | J32: day of
A33: b. | C33: % of Stored Material $ | G33: Notary Public:
B34: (Column F on G703) | G34: My Commission expires:
A35: Total Retainage (Lines 5a + 5b or
B36: Total in Column I of G703) | D36: $ | E36: =D31+D33 -> 0 | G36: CERTIFICATE FOR PAYMENT
A37: 6. TOTAL EARNED LESS RETAINAGE | D37: $ | E37: =E28-E36 -> 518160.63 | G37: In accordance with the Contract Documents, based on on-site observations and the data comprising the
B38: (Line 4 Less Line 5 Total) | G38: application, the Architect or Construction Manager certifies to the Owner that to the best of the
A39: 7. LESS PREVIOUS CERTIFICATES FOR | G39: their knowledge, information and belief the Work has progressed as indicated,
A40: PAYMENT (Line 6 from prior Certificate) | D40: $ | E40: =63513.2+213387.11+208990.32 -> 485890.63 | G40: the quality of the Work is in accordance with the Contract Documents, and the Contractor
A41: 8. CURRENT PAYMENT DUE | D41: $ | E41: =E37-E40 -> 32270 | G41: is entitled to payment of the AMOUNT CERTIFIED.
A42: 9. BALANCE TO FINISH, INCLUDING RETAINAGE $ | E42: =E27-E37 -> 317753.37
B43: (Line 3 less Line 6) | G43: AMOUNT CERTIFIED . . . . . . . . . . . $
A45: CHANGE ORDER SUMMARY | D45: ADDITIONS | E45: DEDUCTIONS | G45: (Attach explanation if amount certified differs from the amount applied. Initial all figures on this
A46: Total changes approved | G46: Application and onthe Continuation Sheet that are changed to conform with the amount certified.)
A47: in previous billing by Owner | D47: =-147685+22356+35327+8868+10889+15953+76154 -> 21862 | G47: ARCHITECT or CONSTRUCTION MANAGER:
A49: Total approved this Billing | D49: 32270 | G49: By: | K49: Date:
A51: TOTALS | D51: =D47+D49+D46 -> 54132 | E51: =E47+E49 -> 0 | G51: This Certificate is not negotiable. The AMOUNT CERTIFIED is payable only to the
G52: Contractor named herein. Issuance, payment and acceptance of payment are without
...

Sheet Continuation Sheet
B1: CONTINUATION SHEET | J1: PAGE OF PAGES | II1: /WGPD
B2: APPLICATION FOR PAYMENT, containing | I2: APPLICATION NO: | J2: =Application!I11 -> 4 | II2: /wir.{d 25}~{r 6}/cf~~{L 6}~
B3: Contractor's signed certification is attached. | I3: APPLICATION DATE: | J3: =Application!I13 Application!I13 -> 44837 | II3: /wgpe
B4: In tabulations below, amounts are stated to the nearest dollar. | I4: JOB NO: | J4: =Application!I16 -> 03011 | II4: /ru.{d 26}
B5: Use Column I on Contracts where variable retainage for line items may apply. | II5: {L 5}
II6: {L 9}
B7: A | C7: B | D7: C | E7: D | F7: E | G7: F | H7: G | J7: H | K7: I | II7: /ru.{d 26}~
B8: ITEM NO. | C8: DESCRIPTION OF WORK | D8: SCHEDULED VALUE | E8: WORK COMPLETED | G8: MATERIALS | H8: TOTAL | I8: % | J8: BALANCE | K8: RETAINAGE
E9: FROM PREVIOUS | F9: THIS PERIOD | G9: PRESENTLY | H9: COMPLETED | I9: (G ÷ C) | J9: TO FINISH | K9: (IF VARIABLE
E10: APPLICATION | G10: STORED | H10: AND STORED | J10: (C - G) | K10: RATE)
E11: (D + E) | G11: (NOT IN | H11: TO DATE
G12: D OR E) | H12: (D+E+F)
B13: 1 | C13: Temporary Construction | D13: 410 | E13: =D13 -> 410 | H13: =IF(E13+F13+G13=0,"",E13+F13+G13) -> 410 | I13: =H13/D13 -> 1 | J13: =IF(D13-H13=0,"",D13-H13) | K13: =H13*10%*0 -> 0
B14: 2 | C14: Site Work & Demolition | D14: 33746 | E14: 33746 | H14: =IF(E14+F14+G14=0,"",E14+F14+G14) -> 33746 | I14: =H14/D14 -> 1 | J14: =IF(D14-H14=0,"",D14-H14) | K14: =H14*10%*0 -> 0
B15: 3 | C15: Concrete | D15: 41370 | E15: =D15*95% -> 39301.5 | H15: =IF(E15+F15+G15=0,"",E15+F15+G15) -> 39301.5 | I15: =H15/D15 -> 0.95 | J15: =IF(D15-H15=0,"",D15-H15) -> 2068.5 | K15: =H15*10%*0 -> 0
B16: 4 | C16: Steel/Masonry/Structural | D16: 22241 | E16: =D16*40% -> 8896.4 | H16: =IF(E16+F16+G16=0,"",E16+F16+G16) -> 8896.4 | I16: =H16/D16 -> 0.4 | J16: =IF(D16-H16=0,"",D16-H16) -> 13344.6 | K16: =H16*10%*0 -> 0
B17: 5 | C17: Carpentry | D17: 10710 | E17: =D17*35% -> 3748.5 | H17: =IF(E17+F17+G17=0,"",E17+F17+G17) -> 3748.5 | I17: =H17/D17 -> 0.35 | J17: =IF(D17-H17=0,"",D17-H17) -> 6961.5 | K17: =H17*10%*0 -> 0
B18: 6 | C18: Wood / Plastics | D18: 19085 | H18: =IF(E18+F18+G18=0,"",E18+F18+G18) | I18: =H18/D18 -> 0 | J18: =IF(D18-H18=0,"",D18-H18) -> 19085 | K18: =H18*10%*0 -> 0
B19: 7 | C19: Thermal/ Moisture Protect | D19: 3451 | H19: =IF(E19+F19+G19=0,"",E19+F19+G19) | I19: =H19/D19 -> 0 | J19: =IF(D19-H19=0,"",D19-H19) -> 3451 | K19: =H19*10%*0 -> 0
B20: 8 | C20: Doors / Glass | D20: 49805.7 | E20: =D20*36% -> 17930.052 | H20: =IF(E20+F20+G20=0,"",E20+F20+G20) -> 17930.052 | I20: =H20/D20 -> 0.36 | J20: =IF(D20-H20=0,"",D20-H20) -> 31875.648 | K20: =H20*10%*0 -> 0
B21: 9 | C21: Finishes - Walls/Frames/Ceiling/Painting (Interior Metal Stud Framing) | D21: 106675.9 | E21: =D21*32% -> 34136.288 | H21: =IF(E21+F21+G21=0,"",E21+F21+G21) -> 34136.288 | I21: =H21/D21 -> 0.32 | J21: =IF(D21-H21=0,"",D21-H21) -> 72539.612 | K21: =H21*10%*0 -> 0
B22: 11 | C22: Specialities (Accessories/Fire Alarm/Hood) | D22: 17697 | E22: =D22*30% -> 5309.1 | H22: =IF(E22+F22+G22=0,"",E22+F22+G22) -> 5309.1 | I22: =H22/D22 -> 0.3 | J22: =IF(D22-H22=0,"",D22-H22) -> 12387.9 | K22: =H22*10%*0 -> 0
B23: 12 | C23: Equipment | D23: 1600 | H23: =IF(E23+F23+G23=0,"",E23+F23+G23) | I23: =H23/D23 -> 0 | J23: =IF(D23-H23=0,"",D23-H23) -> 1600 | K23: =H23*10%*0 -> 0
B24: 13 | C24: Furnishings/Trash Removal | D24: 7177.5 | E24: =D24*100% -> 7177.5 | H24: =IF(E24+F24+G24=0,"",E24+F24+G24) -> 7177.5 | I24: =H24/D24 -> 1 | J24: =IF(D24-H24=0,"",D24-H24) | K24: =H24*10%*0 -> 0
B25: 14 | C25: Mechanical | D25: 202797 | E25: =D25*80% -> 162237.6 | H25: =IF(E25+F25+G25=0,"",E25+F25+G25) -> 162237.6 | I25: =H25/D25 -> 0.8 | J25: =IF(D25-H25=0,"",D25-H25) -> 40559.4 | K25: =H25*10%*0 -> 0
B26: 15 | C26: Plumbing | D26: 11209.2 | E26: =D26*25% -> 2802.3 | H26: =IF(E26+F26+G26=0,"",E26+F26+G26) -> 2802.3 | I26: =H26/D26 -> 0.25 | J26: =IF(D26-H26=0,"",D26-H26) -> 8406.9 | K26: =H26*10%*0 -> 0
B27: 16 | C27: Electrical | D27: 161525.8 | E27: =D27*70% -> 113068.06 | H27: =IF(E27+F27+G27=0,"",E27+F27+G27) -> 113068.06 | I27: =H27/D27 -> 0.7 | J27: =IF(D27-H27=0,"",D27-H27) -> 48457.74 | K27: =H27*10%*0 -> 0
B28: 17 | C28: Fire Life Safety | D28: 6268 | H28: =IF(E28+F28+G28=0,"",E28+F28+G28) | I28: =H28/D28 -> 0 | J28: =IF(D28-H28=0,"",D28-H28) -> 6268 | K28: =H28*10%*0 -> 0
B29: 18 | C29: General Conditions (GA, Superintendent, PM, Office, Admin. Etc) | D29: 26413 | E29: =D29*41% -> 10829.33 | H29: =IF(E29+F29+G29=0,"",E29+F29+G29) -> 10829.33 | I29: =H29/D29 -> 0.41 | J29: =IF(D29-H29=0,"",D29-H29) -> 15583.67 | K29: =H29*10%*0 -> 0
B30: 19 | C30: General Liability Insurance | D30: 25347 | E30: =D30*41% -> 10392.27 | H30: =IF(E30+F30+G30=0,"",E30+F30+G30) -> 10392.27 | I30: =H30/D30 -> 0.41 | J30: =IF(D30-H30=0,"",D30-H30) -> 14954.73 | K30: =H30*10%*0 -> 0
B31: 20 | C31: Contractor's Fee | D31: 34253 | E31: =D31*41% -> 14043.73 | H31: =IF(E31+F31+G31=0,"",E31+F31+G31) -> 14043.73 | I31: =H31/D31 -> 0.41 | J31: =IF(D31-H31=0,"",D31-H31) -> 20209.27 | K31: =H31*10%*0 -> 0
B32: 21 | C32: Approved Additional Tag 1A - Mechanical | D32: -147685 | E32: =D32*100% -> -147685 | H32: =IF(E32+F32+G32=0,"",E32+F32+G32) -> -147685 | I32: =H32/D32 -> 1 | J32: =IF(D32-H32=0,"",D32-H32) | K32: =H32*10%*0 -> 0
B33: 22 | C33: Approved Additional Tag 2A - Asbestos | D33: 22356 | E33: =D33*100% -> 22356 | H33: =IF(E33+F33+G33=0,"",E33+F33+G33) -> 22356 | I33: =H33/D33 -> 1 | J33: =IF(D33-H33=0,"",D33-H33) | K33: =H33*10%*0 -> 0
B34: 23 | C34: Approved Additional Tag 3A - Mechanical 1 unit added | D34: 35327 | E34: =D34*100% -> 35327 | H34: =IF(E34+F34+G34=0,"",E34+F34+G34) -> 35327 | I34: =H34/D34 -> 1 | J34: =IF(D34-H34=0,"",D34-H34) | K34: =H34*10%*0 -> 0
B35: 24 | C35: Approved Additional Tag 4A - Framing, Tiles / Shower Fixtures, plumbing | D35: 8868 | E35: =D35*100% -> 8868 | H35: =IF(E35+F35+G35=0,"",E35+F35+G35) -> 8868 | I35: =H35/D35 -> 1 | J35: =IF(D35-H35=0,"",D35-H35) | K35: =H35*10%*0 -> 0
B36: 25 | C36: Approved Additional Tag 5B - Asbestos Abatement Additional Walls | D36: 10889 | E36: =D36*100% -> 10889 | H36: =IF(E36+F36+G36=0,"",E36+F36+G36) -> 10889 | I36: =H36/D36 -> 1 | J36: =IF(D36-H36=0,"",D36-H36) | K36: =H36*10%*0 -> 0
B37: 26 | C37: Approved Additional Tag 6A - Demo for Asbestos additional walls added | D37: 15953 | E37: =D37 -> 15953 | H37: =IF(E37+F37+G37=0,"",E37+F37+G37) -> 15953 | I37: =H37/D37 -> 1 | J37: =IF(D37-H37=0,"",D37-H37) | K37: =H37*10%*0 -> 0
B38: 27 | C38: Approved Additional Tag 7A - Demo 2nd Floor / Concrete new power,Floor drains / Mechanical Front Office / Exterior Painting | D38: 76154 | E38: =D38 -> 76154 | H38: =IF(E38+F38+G38=0,"",E38+F38+G38) -> 76154 | I38: =H38/D38 -> 1 | J38: =IF(D38-H38=0,"",D38-H38) | K38: =H38*10%*0 -> 0
B39: 28 | C39: Approved Additional Tag 8A | D39: 32270 | F39: =D39 -> 32270 | H39: =IF(E39+F39+G39=0,"",E39+F39+G39) -> 32270 | I39: =H39/D39 -> 1 | J39: =IF(D39-H39=0,"",D39-H39) | K39: =H39*10%*0 -> 0
F41: =D41*23% -> 0 | I41: =H41/D41 -> #DIV/0!
...
