Workbook

Sheet Systems Summary
D2: Summary - Mr. Jay Immigration Lawyer Office | I2: Contractors’ Lic # 926663
D3: Version 1A
B5: Special Note: | D5: Complete Project Includes working 5 days/week for all trades under Bains Dev.
B7: Project: | D7: 356 S Daniel Way, San Jose, CA 95128 | F7: Project Type: | I7: TI
B8: Location: | D8: Close to Santana Row | F8: Structure Type: | I8: Tilt Up
F9: No. Stories Below Grade: | I9: NA
F10: No. Stories Above Grade: | I10: 1
F11: No. of Units: | I11: 2
B12: Architect: | D12: N/A | F12: No. of Bathrooms: | I12: 2
B13: Drawgings | D13: Drawings by Architects Julio
B15: Int. Design | F15: Off-Site Area: | I15: 0 | J15: SF
F16: TI Building Area: | I16: 8720 | J16: SF
B17: Est. Date: | D17: 44783 | F17: Lease Space/TI Area: | I17: 8720 | J17: SF
F18: Common Area: | I18: NA | J18: SF
B19: Contact: | D19: Vagish Kapila - (cell) 408-410-6151; vkapila@bainsdev.com | F19: Unit Area: | I19: NA | J19: SF
F20: Garage Area: | I20: NA | J20: SF
I22: TOTAL | J22: COST
B23: SECT | D23: DESCRIPTION | F23: Details | I23: COST | J23: PER SF
B25: 01000 | D25: Temporary Construction | I25: ='Off-Site Summary'!H17+'Site Summary'!H17+'Garage Summary'!H17+'Building Summary'!H22 -> 410 | J25: =I25/I17 -> 0.047018349
B26: ='Building Detail'!B26 -> 01100 | D26: ='Building Detail'!D26 -> Scaffold/Demo Scrapper | F26: ='Building Detail'!J26 -> NIC | I26: ='Building Detail'!H26 -> 0 | J26: ='Building Detail'!I35 -> 0
B27: ='Building Detail'!B27 -> 01200 | D27: ='Building Detail'!D27 -> Signs and Menu | F27: ='Building Detail'!J27 -> NIC | I27: ='Building Detail'!H27 -> 410 | J27: ='Building Detail'!I36 -> 0
B29: 02000 | D29: Site Work & Demolition | I29: ='Off-Site Summary'!H18+'Site Summary'!H18+'Garage Summary'!H18+'Building Summary'!H23 -> 117617 | J29: =I29/I17 -> 13.488188
B30: ='Building Detail'!B34 -> 02150 | D30: ='Building Detail'!D34 -> Demolition | F30: ='Building Detail'!J34 -> Includes inside demo for the space per the plan. Includes ceiling demo, all carpet to be removed and floor glue removed, demo of 2 bathrooms, demo all tiles in the bathroom. Includes asbestos demo allowance for $40k. Also includes demo of entire offices to make it an open ceiling design | I30: ='Building Detail'!H34 -> 83776
B31: ='Building Detail'!B35 -> 02175 | D31: ='Building Detail'!D35 -> Dewatering, Sidwalk Repair | F31: ='Building Detail'!J35 -> Includes demo of part of existing side walk to create a new ADA drive way per drawings | I31: ='Building Detail'!H35 -> 24970 | J31: ='Building Detail'!I40 -> 0
B32: ='Building Detail'!B36 -> 02180 | D32: ='Building Detail'!D36 -> Landscaping | I32: ='Building Detail'!H36 -> 0 | J32: ='Building Detail'!I41 -> 0
B33: ='Building Detail'!B37 -> 02190 | D33: ='Building Detail'!D37 -> Waterproofing | F33: ='Building Detail'!J37 -> May be needed for shower room | I33: ='Building Detail'!H37 -> 8871
B35: 03000 | D35: Concrete | I35: ='Off-Site Summary'!H19+'Site Summary'!H19+'Garage Summary'!H19+'Building Summary'!H24 -> 73149 | J35: =I35/I17 -> 8.3886468
B36: ='Building Detail'!B43 -> 03100 | D36: ='Building Detail'!D43 -> Asphalt/Striping/Seting | I36: ='Building Detail'!H43 -> 11710 | J36: ='Building Detail'!I44 -> 0
B37: ='Building Detail'!B44 -> 03200 | D37: ='Building Detail'!D44 -> Concrete Cutting/Pouring/Coring | F37: ='Building Detail'!J44 -> Includes new coring for shower room and sauna | I37: ='Building Detail'!H44 -> 18779 | J37: ='Building Detail'!I45 -> 0
B38: ='Building Detail'!B45 -> 03400 | D38: ='Building Detail'!D45 -> Repair/Rebuild Side Walks | F38: ='Building Detail'!J45 -> Includes new sidewalk, w/o handrail to be build for ADA access and create a new enterance to the new door/space | I38: ='Building Detail'!H45 -> 42660 | J38: ='Building Detail'!I46 -> 0
B39: ='Building Detail'!B46 -> 03500 | D39: ='Building Detail'!D46 -> Stucco | I39: ='Building Detail'!H46 -> 0 | J39: ='Building Detail'!I47 -> 0
B41: ='Building Detail'!B50 -> 05000 | D41: ='Building Detail'!D50 -> STEEL/MASONRY/STRUCTURAL | F41: ='Building Detail'!J56 -> Includes structural support for 3 new HVAC units on the roof | I41: ='Building Detail'!H58 -> 60180 | J41: ='Building Detail'!I58 -> 6.9013761
B42: ='Building Detail'!B51 -> 05200 | D42: ='Building Detail'!D51 -> Miscellaneous/Decorative metals | F42: ='Building Detail'!J51 -> NIC | I42: ='Building Detail'!H51 -> 0
B43: ='Building Detail'!B52 -> 05300 | D43: ='Building Detail'!D52 -> Steel stairs | F43: ='Building Detail'!J52 -> Includes repairing of current stairs to a new floating stairs | I43: ='Building Detail'!H52 -> 19334
B44: ='Building Detail'!B53 -> 05400 | D44: ='Building Detail'!D53 -> Cultured Stone - Façade & Planter Caps | F44: ='Building Detail'!J53 -> Includes new stones in the lobby area | I44: ='Building Detail'!H53 -> 29445
B45: ='Building Detail'!B54 -> 05500 | D45: ='Building Detail'!D54 -> Metal Awning | F45: ='Building Detail'!J54 -> N/A | I45: ='Building Detail'!H54 -> 0
B46: ='Building Detail'!B55 -> 05600 | D46: ='Building Detail'!D55 -> Repair Concrete floor | F46: ='Building Detail'!J55 -> Includes minor crack/repiar on the 2nd floor after remoing old carpet | I46: ='Building Detail'!H55 -> 3271
B47: ='Building Detail'!B56 -> 05700 | D47: ='Building Detail'!D56 -> Sturctural Support | F47: ='Building Detail'!J56 -> Includes structural support for 3 new HVAC units on the roof | I47: ='Building Detail'!H56 -> 8130
B49: ='Building Detail'!B60 -> 55000 | D49: ='Building Detail'!D60 -> Carpentry | I49: ='Building Detail'!H66 -> 10710 | J49: =I49/I17 -> 1.228211
B50: ='Building Detail'!B61 -> 05510 | D50: ='Building Detail'!D69 -> Rough Framing | F50: ='Building Detail'!J61 -> Rough carpentry needed to repair minor ceiling grids. Repair only. Repair in 6 areas included | I50: ='Building Detail'!H61 -> 10710
...

Sheet Building Summary
B7: Project: | D7: ='Systems Summary'!D12 -> N/A | E7: Project Type: | H7: TI
B8: Location: | D8: ='Systems Summary'!D8 -> Close to Santana Row | E8: Structure Type: | H8: Steel Frame
D9: ='Systems Summary'!D9 -> 0 | E9: No. Stories Below Grade: | H9: NA
E10: No. Stories Above Grade: | H10: 5
E11: No. of Units: | H11: NA
B12: Architect: | D12: Allied Architects | E12: No. of Bathrooms: | H12: NA
B13: Drawgings | D13: ='Systems Summary'!D13 -> Drawings by Architects Julio
D14: 3.0, 4.0, 4.1, 4.3, 4.4, 4.5, 5, 5.1, 5.2
B15: Int. Design | E15: Off-Site Area: | H15: NA | I15: SF
E16: Lease Space/TI Area: | H16: 5802 | I16: SF
B17: Est. Date: | D17: 40774 | E17: Gross Building Area: | H17: 5802 | I17: SF
E18: Common Area: | H18: NA | I18: SF
B20: SECT | D20: DESCRIPTION | E20: QUANT | F20: UNIT | G20: COST | H20: COST | I20: PER SF
B22: 01000 | D22: Temporary Construction | H22: ='Building Detail'!H30 -> 410
B23: 02000 | D23: Site Work & Demolition | H23: ='Building Detail'!H39 -> 117617
B24: 03000 | D24: Concrete | H24: ='Building Detail'!H48 -> 73149
B25: 05000 | D25: Steel | H25: ='Building Detail'!H58 -> 60180
B26: 06000 | D26: Wood / Plastics | H26: ='Building Detail'!H79 -> 41085
B27: 07000 | D27: Thermal / Moisture Protection | H27: ='Building Detail'!H89 -> 15721
B28: 08000 | D28: Doors / Glass | H28: ='Building Detail'!H98 -> 89423.7
B29: 09000 | D29: Finishes | H29: ='Building Detail'!H115 -> 185839.9
B30: 10000 | D30: Specialties | H30: ='Building Detail'!H126 -> 18089
B31: 11000 | D31: Equipment | H31: ='Building Detail'!H136 -> 1600
B32: 12000 | D32: Furnishings | H32: ='Building Detail'!H144 -> 16077.6
B33: 14000 | D33: Conveying Systems | H33: ='Building Detail'!H147 -> 0
B34: 15000 | D34: Mechanical | H34: ='Building Detail'!H155 -> 131913
B35: ='Building Detail'!B162 -> 152000 | D35: ='Building Detail'!D162 -> Plumbing | H35: ='Building Detail'!H162 -> 0
B36: 16000 | D36: Electrical | H36: ='Building Detail'!H174 -> 267820.8
D39: Subtotal | H39: =SUM(H21:H37) -> 1018926
D41: General Conditions
D42: Builders Risk Insurance
D43: General Liability Insurance
D44: Bond
D45: Overhead
D46: Contractor's Fee
D49: Subtotal | H49: =SUM(H38:H47) -> 1018926
D51: Contractor's Contingency
D54: BUILDING TOTAL COST | H54: =SUM(H48:H52) -> 1018926

Sheet Building Detail
D3: Building Bid DETAILS Sheet
B7: Project: | D7: ='Systems Summary'!D7 -> 356 S Daniel Way, San Jose, CA 95128 | E7: Project Type: | H7: TI
B8: Location: | D8: ='Systems Summary'!D8 -> Close to Santana Row | E8: Structure Type: | H8: Conc Block
E9: No. Stories Below Grade: | H9: NA
D10: San Jose, CA | E10: No. Stories Above Grade: | H10: 1
E11: No. of Units: | H11: NA
B12: Architect: | D12: ='Systems Summary'!D12 -> N/A | E12: No. of Bathrooms: | H12: NA
B13: Drawgings | D13: ='Systems Summary'!D13 -> Drawings by Architects Julio
B15: Int. Design | E15: Off-Site Area: | H15: NA | I15: SF
E16: Lease Space/TI Area: | H16: ='Systems Summary'!I16 -> 8720 | I16: SF
B17: Est. Date: | D17: ='Systems Summary'!D17 -> 44783 | E17: Gross Building Area: | H17: ='Systems Summary'!I17 -> 8720 | I17: SF | K17: Change Date
E18: Common Area: | H18: NA | I18: SF
B19: Contact: | D19: Vagish Kapila - (cell) 408-410-6151; vkpaila@bainsdev.com | E19: Unit Area: | H19: NA | I19: SF
D20: Raj - (cell) 510-432-8288; raj@bainsdev.com | E20: Garage Area: | H20: NA | I20: SF
H22: TOTAL | I22: COST | J22: Details
B23: SECT | D23: DESCRIPTION | E23: Details | H23: COST | I23: PER SF
B25: 01000 | D25: TEMPORARY CONSTRUCTION
B26: 01100 | D26: Scaffold/Demo Scrapper | E26: 0 | F26: SF | G26: 3 | H26: =G26*E26*38% -> 0 | J26: NIC
B27: 01200 | D27: Signs and Menu | E27: 1 | F27: SF | G27: 410 | H27: =G27*E27 -> 410 | J27: NIC
D30: Temporary Construction Totals | H30: =SUM(H25:H28) -> 410 | I30: =H30/H17 -> 0.047018349
B33: 02000 | D33: SITE WORK
B34: 02150 | D34: Demolition | E34: 1 | F34: LS | G34: 83776 | H34: =E34*G34 -> 83776 | J34: Includes inside demo for the space per the plan. Includes ceiling demo, all carpet to be removed and floor glue removed, demo of 2 bathrooms, demo all tiles in the bathroom. Includes asbestos demo allowance for $40k. Also includes demo of entire offices to make it an open ceiling design
B35: 02175 | D35: Dewatering, Sidwalk Repair | E35: 1 | F35: SF | G35: 24970 | H35: =E35*G35 -> 24970 | J35: Includes demo of part of existing side walk to create a new ADA drive way per drawings
B36: 02180 | D36: Landscaping | E36: 0 | F36: LS | G36: 5400 | H36: =E36*G36 -> 0
B37: 02190 | D37: Waterproofing | E37: 1 | F37: LS | G37: 8871 | H37: =E37*G37 -> 8871 | J37: May be needed for shower room
D39: Site Work Totals | H39: =SUM(H33:H37) -> 117617 | I39: =H39/H17 -> 13.488188
B42: 03000 | D42: CONCRETE/STUCCO/ASHPALT
B43: 03100 | D43: Asphalt/Striping/Seting | E43: 1 | F43: LS | G43: 11710 | H43: =E43*G43 -> 11710 | J43: Includes re-stripping of the back parking lot and shaving just the ADA parking spot
B44: 03200 | D44: Concrete Cutting/Pouring/Coring | E44: 1 | F44: LS | G44: 18779 | H44: =E44*G44 -> 18779 | J44: Includes new coring for shower room and sauna
B45: 03400 | D45: Repair/Rebuild Side Walks | E45: 1 | F45: LS | G45: 42660 | H45: =E45*G45 -> 42660 | J45: Includes new sidewalk, w/o handrail to be build for ADA access and create a new enterance to the new door/space
B46: 03500 | D46: Stucco | E46: 0 | F46: LS | G46: 12800 | H46: =E46*G46 -> 0
D48: Concrete Totals | H48: =SUM(H42:H46) -> 73149 | I48: =H48/H17 -> 8.3886468
B50: 05000 | D50: STEEL/MASONRY/STRUCTURAL
B51: 05200 | D51: Miscellaneous/Decorative metals | E51: 0 | F51: LS | G51: 5500 | H51: =E51*G51 -> 0 | J51: NIC
B52: 05300 | D52: Steel stairs | E52: 1 | F52: FLT | G52: 19334 | H52: =E52*G52 -> 19334 | J52: Includes repairing of current stairs to a new floating stairs
B53: 05400 | D53: Cultured Stone - Façade & Planter Caps | E53: 1 | F53: LS | G53: 29445 | H53: =E53*G53 -> 29445 | J53: Includes new stones in the lobby area
B54: 05500 | D54: Metal Awning | E54: 0 | F54: LS | G54: 3200 | H54: =E54*G54 -> 0 | J54: N/A
B55: 05600 | D55: Repair Concrete floor | E55: 1 | F55: LS | G55: 3271 | H55: =E55*G55 -> 3271 | J55: Includes minor crack/repiar on the 2nd floor after remoing old carpet
B56: 05700 | D56: Sturctural Support | E56: 3 | F56: LF | G56: 2710 | H56: =E56*G56 -> 8130 | J56: Includes structural support for 3 new HVAC units on the roof
D58: Steel Totals | H58: =SUM(H51:H56) -> 60180 | I58: =H58/H17 -> 6.9013761
...

Sheet General Conditions
C5: Project Duration:
C6: Projected Staff:
B9: ITEM | F9: UNIT | G9: TOTAL
B10: NO. | C10: DESCRIPTION | D10: QUANT | E10: UNIT | F10: COST | G10: COST
B12: SITE MANAGEMENT
B13: 1 | C13: Senior Project Manager | E13: WK | F13: =120*40 -> 4800 | G13: =D13*F13 -> 0
B14: 2 | C14: Project Manager | D14: 19 | E14: WK | F14: =55*30 -> 1650 | G14: =D14*F14*38% -> 11913
B15: 3 | C15: Assistant Project Manager | E15: WK | G15: =D15*F15 -> 0
B16: 4 | C16: Project Superintendant | D16: 16 | E16: WK | F16: =87*32 -> 2784 | G16: =D16*F16*38% -> 16926.72
B17: 5 | C17: Assistant Superintendant | E17: WK | G17: =D17*F17 -> 0
B18: 6 | C18: Project Engineer | E18: WK | G18: =D18*F18 -> 0
B19: 7 | C19: Assistant Project Engineer | E19: WK | G19: =D19*F19 -> 0
B20: 8 | C20: Form Detailer | E20: HR | G20: =D20*F20 -> 0
B21: 9 | C21: Project Secretary | E21: WK | G21: =D21*F21 -> 0
B22: 10 | C22: Project Accountant | D22: 7 | E22: MO | F22: =50*43 -> 2150 | G22: =D22*F22*38% -> 5719
B23: 11 | C23: MEP Coordinator | E23: HR | G23: =D23*F23 -> 0
B24: 12 | C24: EEO Coordinator | E24: WK | G24: =D24*F24 -> 0
B25: 13 | C25: Contract Administrator | E25: WK | G25: =D25*F25 -> 0
B26: 14 | C26: Safety Coordinator | D26: 88 | E26: HR | F26: 87 | G26: =D26*F26*38% -> 2909.28
B27: 15 | C27: Scheduling | E27: HR | F27: 65 | G27: =D27*F27 -> 0
B29: JOBSITE OFFICE
B30: 16 | C30: Office Rent | E30: MO | G30: =D30*F30 -> 0
B31: 17 | C31: Trailers | E31: MO | F31: 500 | G31: =D31*F31 -> 0
B32: 18 | C32: Site set-up / Mobilization (Move from trailer) | E32: LS | F32: 1500 | G32: =D32*F32 -> 0
B33: 19 | C33: Demobilization | E33: LS | F33: 3500 | G33: =D33*F33 -> 0
B34: 20 | C34: Jobsite Office Equipment / Furniture | E34: LS | F34: 1800 | G34: =D34*F34 -> 0
B35: 21 | C35: Office Supplies | E35: MO | F35: 125 | G35: =D35*F35 -> 0
B36: 22 | C36: Telephone / Fax | E36: LS | F36: 500 | G36: =D36*F36 -> 0
B37: 23 | C37: Telephone / Fax Monthly Operational Costs | E37: MO | F37: 125 | G37: =D37*F37 -> 0
B38: 24 | C38: Copier / Supplies / Maintenance | E38: MO | F38: 275 | G38: =D38*F38 -> 0
B39: 25 | C39: Project Sign | D39: 2 | E39: EA | F39: 225 | G39: =D39*F39*38% -> 171
B40: 26 | C40: Project Schedule | E40: MO | G40: =D40*F40 -> 0
B41: 27 | C41: Plan & Specification Printing (by Owner) | E41: LS | G41: =D41*F41 -> 0
B42: 28 | C42: Scaffolding | D42: 1 | E42: LS | F42: 720 | G42: =D42*F42*38% -> 273.6
B43: 29 | C43: Miscellaneous Reproduction | E43: LS | G43: =D43*F43 -> 0
B44: 30 | C44: Security | E44: MO | F44: 1250 | G44: =D44*F44 -> 0
B46: VEHICLES & TRAVEL
B47: 31 | C47: Truck Expense / Plant Vehicles | E47: MO | F47: 575 | G47: =D47*F47 -> 0
B48: 32 | C48: Gas / Oil | E48: MO | F48: 250 | G48: =D48*F48 -> 0
B49: 33 | C49: Miscellaneous Truck Repairs | E49: LS | G49: =D49*F49 -> 0
...

Sheet Off-Site Summary
A1: Project: | D1: ='Systems Summary'!D7 -> 356 S Daniel Way, San Jose, CA 95128 | E1: Project Type: | H1: ='Systems Summary'!I7 -> TI
A2: Location: | D2: ='Systems Summary'!D8 -> Close to Santana Row | E2: Structure Type: | H2: ='Systems Summary'!I8 -> Tilt Up
E3: No. Stories Below Grade: | H3: ='Systems Summary'!I9 -> NA
E4: No. Stories Above Grade: | H4: ='Systems Summary'!I10 -> 1
A5: Architect: | D5: ='Systems Summary'!D12 -> N/A | E5: No. of Units: | H5: ='Systems Summary'!I11 -> 2
E6: No. of Bathrooms: | H6: ='Systems Summary'!I12 -> 2
E7: Off-Site Area: | H7: ='Systems Summary'!I15 -> 0 | I7: SF
E8: Site Area: | H8: ='Systems Summary'!I16 -> 8720 | I8: SF
E9: ='Systems Summary'!F17 -> Lease Space/TI Area: | H9: ='Systems Summary'!I17 -> 8720 | I9: SF
E10: Common Area: | H10: ='Systems Summary'!I18 -> NA | I10: SF
E11: Unit Area: | H11: ='Systems Summary'!I19 -> NA | I11: SF
E12: Garage Area: | H12: ='Systems Summary'!I20 -> NA | I12: SF
B14: SPEC | G14: UNIT | H14: TOTAL | I14: COST
B15: SECT | D15: DESCRIPTION | E15: QUANT | F15: UNIT | G15: COST | H15: COST | I15: PER SF
B17: 01000 | D17: Temporary Construction | H17: ='Off-Site Detail'!H27 -> 0
B18: 02000 | D18: Site Work | H18: ='Off-Site Detail'!H65 -> 0
B19: 03000 | D19: Concrete | H19: ='Off-Site Detail'!H78 -> 0
B20: 04000 | D20: Masonry | H20: ='Off-Site Detail'!H88 -> 0
B21: 05000 | D21: Steel | H21: ='Off-Site Detail'!H98 -> 0
B22: 06000 | D22: Wood / Plastics | H22: ='Off-Site Detail'!H108 -> 0
B23: 07000 | D23: Thermal / Moisture Protection | H23: ='Off-Site Detail'!H118 -> 0
B24: 08000 | D24: Doors / Glass | H24: ='Off-Site Detail'!H128 -> 0
B25: 09000 | D25: Finishes | H25: ='Off-Site Detail'!H138 -> 0
B26: 10000 | D26: Specialties | H26: ='Off-Site Detail'!H148 -> 0
B27: 11000 | D27: Equipment | H27: ='Off-Site Detail'!H158 -> 0
B28: 12000 | D28: Furnishings | H28: ='Off-Site Detail'!H168 -> 0
B29: 13000 | D29: Special Construction (Water Fountain) | H29: ='Off-Site Detail'!H178 -> 0
B30: 14000 | D30: Conveying Systems | H30: ='Off-Site Detail'!H188 -> 0
B31: 15000 | D31: Mechanical | H31: ='Off-Site Detail'!H198 -> 0
B32: 16000 | D32: Electrical | H32: ='Off-Site Detail'!H208 -> 0
D35: Subtotal | H35: =SUM(H16:H33) -> 0
D37: General Conditions
D38: Builders Risk Insurance
D39: General Liability Insurance
D40: Bond
D41: Overhead
D42: Contractor's Fee
D45: Subtotal | H45: =SUM(H34:H43) -> 0
D47: Contractor's Contingency
D50: OFF-SITE TOTAL COST | H50: =SUM(H44:H48) -> 0

Sheet Off-Site Detail
A1: Project: | D1: ='Systems Summary'!D7 -> 356 S Daniel Way, San Jose, CA 95128 | E1: Project Type: | H1: ='Systems Summary'!I7 -> TI
A2: Location: | D2: ='Systems Summary'!D8 -> Close to Santana Row | E2: Structure Type: | H2: ='Systems Summary'!I8 -> Tilt Up
E3: No. Stories Below Grade: | H3: ='Systems Summary'!I9 -> NA
E4: No. Stories Above Grade: | H4: ='Systems Summary'!I10 -> 1
A5: Architect: | D5: ='Systems Summary'!D12 -> N/A | E5: No. of Units: | H5: ='Systems Summary'!I11 -> 2
E6: No. of Bathrooms: | H6: ='Systems Summary'!I12 -> 2
E7: Off-Site Area: | H7: ='Systems Summary'!I15 -> 0
E8: Site Area: | H8: ='Systems Summary'!I16 -> 8720
E9: ='Systems Summary'!F17 -> Lease Space/TI Area: | H9: ='Systems Summary'!I17 -> 8720 | I9: SF
E10: Common Area: | H10: ='Systems Summary'!I18 -> NA | I10: SF
E11: Unit Area: | H11: ='Systems Summary'!I19 -> NA | I11: SF
E12: ='Systems Summary'!F20 -> Garage Area: | H12: ='Systems Summary'!I20 -> NA
B14: SPEC | G14: UNIT | H14: TOTAL | I14: COST
B15: SECT | D15: DESCRIPTION | E15: QUANT | F15: UNIT | G15: COST | H15: COST | I15: PER SF
B17: 01000 | D17: TEMPORARY CONSTRUCTION
B18: 01100 | D18: Scaffold | F18: SF | H18: =E18*G18 -> 0
B19: 01150 | D19: Temporary roads | F19: SF | H19: =E19*G19 -> 0
B20: 01200 | D20: Barricades | F20: EA | H20: =E20*G20 -> 0
B21: 01250 | D21: Traffic control | F21: LS | H21: =E21*G21 -> 0
B22: 01260 | D22: Flagman | F22: LS | H22: =E22*G22 -> 0
B23: 01270 | D23: Safety rails | F23: LF | H23: =E23*G23 -> 0
D27: Temporary Construction Totals | H27: =SUM(H17:H25) -> 0 | I27: =H27/H9 -> 0
B30: 02000 | D30: SITE WORK
B31: 02050 | D31: Mobilizations | E31: 0 | F31: LS | G31: 5000 | H31: =E31*G31 -> 0
B32: 02100 | D32: Clear and grub | F32: SF | H32: =E32*G32 -> 0
B33: 02105 | D33: Protect (e) trees | F33: EA | H33: =E33*G33 -> 0
B34: 02150 | D34: Demolition | F34: SF | H34: =E34*G34 -> 0
B35: 02175 | D35: Dewatering | F35: SF | H35: =E35*G35 -> 0
B36: 02550 | D36: Site Utilities:
D37: Sanitary Sewer | F37: LF | H37: =E37*G37 -> 0
D38: Storm Drain | F38: LF | H38: =E38*G38 -> 0
D39: - 18" RCP | F39: LF | H39: =E39*G39 -> 0
D40: - 15" RCP | F40: LF | H40: =E40*G40 -> 0
D41: - 12" RCP | F41: LF | H41: =E41*G41 -> 0
D42: - 10" RCP | F42: LF | H42: =E42*G42 -> 0
D43: - 8" RCP | F43: LF | H43: =E43*G43 -> 0
D44: - 6" RCP | F44: LF | H44: =E44*G44 -> 0
D45: - Tie to (e) manhole | F45: LS | H45: =E45*G45 -> 0
D46: - Catch basins | F46: EA | H46: =E46*G46 -> 0
D47: - Curb inlets | F47: EA | H47: =E47*G47 -> 0
...

Sheet Site Summary
A1: Project: | D1: ='Systems Summary'!D7 -> 356 S Daniel Way, San Jose, CA 95128 | E1: Project Type: | H1: ='Systems Summary'!I7 -> TI
A2: Location: | D2: ='Systems Summary'!D8 -> Close to Santana Row | E2: Structure Type: | H2: ='Systems Summary'!I8 -> Tilt Up
E3: No. Stories Below Grade: | H3: ='Systems Summary'!I9 -> NA
E4: No. Stories Above Grade: | H4: ='Systems Summary'!I10 -> 1
A5: Architect: | D5: ='Systems Summary'!D12 -> N/A | E5: No. of Units: | H5: ='Systems Summary'!I11 -> 2
D6: ='Systems Summary'!D15 -> 0 | E6: No. of Bathrooms: | H6: ='Systems Summary'!I12 -> 2
E7: Off-Site Area: | H7: ='Systems Summary'!I15 -> 0 | I7: SF
E8: Site Area: | H8: ='Systems Summary'!I16 -> 8720 | I8: SF
E9: ='Systems Summary'!F17 -> Lease Space/TI Area: | H9: ='Systems Summary'!I17 -> 8720 | I9: SF
E10: Common Area: | H10: ='Systems Summary'!I18 -> NA | I10: SF
E11: Unit Area: | H11: ='Systems Summary'!I19 -> NA | I11: SF
E12: Garage Area: | H12: ='Systems Summary'!I20 -> NA | I12: SF
B14: SPEC | G14: UNIT | H14: TOTAL | I14: COST
B15: SECT | D15: DESCRIPTION | E15: QUANT | F15: UNIT | G15: COST | H15: COST | I15: PER SF
B17: 01000 | D17: Temporary Construction | H17: ='Site Detail'!H27 -> 0
B18: 02000 | D18: Site Work | H18: ='Site Detail'!H67 -> 0
B19: 03000 | D19: Concrete | H19: ='Site Detail'!H84 -> 0
B20: 04000 | D20: Masonry | H20: ='Site Detail'!H94 -> 0
B21: 05000 | D21: Steel | H21: ='Site Detail'!H104 -> 0
B22: 06000 | D22: Wood / Plastics | H22: ='Site Detail'!H114 -> 0
B23: 07000 | D23: Thermal / Moisture Protection | H23: ='Site Detail'!H124 -> 0
B24: 08000 | D24: Doors / Glass | H24: ='Site Detail'!H134 -> 0
B25: 09000 | D25: Finishes | H25: ='Site Detail'!H144 -> 0
B26: 10000 | D26: Specialties | H26: ='Site Detail'!H154 -> 0
B27: 11000 | D27: Equipment | H27: ='Site Detail'!H164 -> 0
B28: 12000 | D28: Furnishings | H28: ='Site Detail'!H174 -> 0
B29: 13000 | D29: Special Construction | H29: ='Site Detail'!H184 -> 0
B30: 14000 | D30: Conveying Systems | H30: ='Site Detail'!H194 -> 0
B31: 15000 | D31: Mechanical | H31: ='Site Detail'!H204 -> 0
B32: 16000 | D32: Electrical | H32: ='Site Detail'!H216 -> 0
D35: Subtotal | H35: =SUM(H16:H33) -> 0
D37: General Conditions
D38: Builders Risk Insurance
D39: General Liability Insurance
D40: Bond
D41: Overhead
D42: Contractor's Fee
D45: Subtotal | H45: =SUM(H34:H43) -> 0
D47: Contractor's Contingency
D50: SITE TOTAL COST | H50: =SUM(H44:H48) -> 0

Sheet Site Detail
A1: Project: | D1: ='Systems Summary'!D7 -> 356 S Daniel Way, San Jose, CA 95128 | E1: Project Type: | H1: ='Systems Summary'!I7 -> TI
A2: Location: | D2: ='Systems Summary'!D8 -> Close to Santana Row | E2: Structure Type: | H2: ='Systems Summary'!I8 -> Tilt Up
E3: No. Stories Below Grade: | H3: ='Systems Summary'!I9 -> NA
E4: No. Stories Above Grade: | H4: ='Systems Summary'!I10 -> 1
A5: Architect: | D5: ='Systems Summary'!D12 -> N/A | E5: No. of Units: | H5: ='Systems Summary'!I11 -> 2
D6: ='Systems Summary'!D15 -> 0 | E6: No. of Bathrooms: | H6: ='Systems Summary'!I12 -> 2
E7: Off-Site Area: | H7: ='Systems Summary'!I15 -> 0 | I7: SF
E8: Site Area: | H8: ='Systems Summary'!I16 -> 8720 | I8: SF
E9: ='Systems Summary'!F17 -> Lease Space/TI Area: | H9: ='Systems Summary'!I17 -> 8720 | I9: SF
E10: Common Area: | H10: ='Systems Summary'!I18 -> NA | I10: SF
E11: Unit Area: | H11: ='Systems Summary'!I19 -> NA | I11: SF
E12: Garage Area: | H12: ='Systems Summary'!I20 -> NA | I12: SF
B14: SPEC | G14: UNIT | H14: TOTAL | I14: COST
B15: SECT | D15: DESCRIPTION | E15: QUANT | F15: UNIT | G15: COST | H15: COST | I15: PER SF
B17: 01000 | D17: TEMPORARY CONSTRUCTION
B18: 01100 | D18: Scaffold | F18: SF | H18: =E18*G18 -> 0
B19: 01150 | D19: Temporary roads | F19: SF | H19: =E19*G19 -> 0
B20: 01200 | D20: Barricades | F20: EA | G20: 65 | H20: =E20*G20 -> 0
B21: 01250 | D21: Traffic control | F21: LS | G21: 2500 | H21: =E21*G21 -> 0
B22: 01260 | D22: Flagman | F22: LS | H22: =E22*G22 -> 0
B23: 01270 | D23: Safety rails | F23: LF | H23: =E23*G23 -> 0
D27: Temporary Construction Totals | H27: =SUM(H17:H25) -> 0 | I27: =H27/H9 -> 0
B30: 02000 | D30: SITE WORK
B31: 02050 | D31: Mobilizations | F31: LS | G31: 5000 | H31: =E31*G31 -> 0
B32: 02100 | D32: Clear and grub | F32: SF | G32: 1 | H32: =E32*G32 -> 0
B33: 02105 | D33: Protect (e) trees | F33: EA | H33: =E33*G33 -> 0
B34: 02150 | D34: Demolition | F34: SF | G34: 1.5 | H34: =E34*G34 -> 0
B35: 02175 | D35: Dewatering | F35: SF | H35: =E35*G35 -> 0
B36: 02550 | D36: Site Utilities:
D37: Sanitary Sewer | F37: LS | G37: 10000 | H37: =E37*G37 -> 0
D38: - Tie to (e) manhole | F38: LS | G38: 2000 | H38: =E38*G38 -> 0
D39: Storm Drain | F39: LS | G39: 15000 | H39: =E39*G39 -> 0
D40: - 18" RCP | F40: LF | H40: =E40*G40 -> 0
D41: - 15" RCP | F41: LF | H41: =E41*G41 -> 0
D42: - 12" RCP | F42: LF | H42: =E42*G42 -> 0
D43: - 10" RCP | F43: LF | H43: =E43*G43 -> 0
D44: - 8" RCP | F44: LF | H44: =E44*G44 -> 0
D45: - 6" RCP | F45: LF | H45: =E45*G45 -> 0
D46: - Tie to (e) manhole | F46: LS | G46: 1500 | H46: =E46*G46 -> 0
D47: - Catch basins | F47: EA | H47: =E47*G47 -> 0
...

Sheet Garage Summary
A1: Project: | D1: ='Systems Summary'!D7 -> 356 S Daniel Way, San Jose, CA 95128 | E1: Project Type: | H1: ='Systems Summary'!I7 -> TI
A2: Location: | D2: ='Systems Summary'!D8 -> Close to Santana Row | E2: Structure Type: | H2: ='Systems Summary'!I8 -> Tilt Up
E3: No. Stories Below Grade: | H3: ='Systems Summary'!I9 -> NA
E4: No. Stories Above Grade: | H4: ='Systems Summary'!I10 -> 1
A5: Architect: | D5: ='Systems Summary'!D12 -> N/A | E5: No. of Units: | H5: ='Systems Summary'!I11 -> 2
E6: No. of Bathrooms: | H6: ='Systems Summary'!I12 -> 2
E7: Off-Site Area: | H7: ='Systems Summary'!I15 -> 0 | I7: SF
E8: Site Area: | H8: ='Systems Summary'!I16 -> 8720 | I8: SF
E9: ='Systems Summary'!F17 -> Lease Space/TI Area: | H9: ='Systems Summary'!I17 -> 8720 | I9: SF
E10: Common Area: | H10: ='Systems Summary'!I18 -> NA | I10: SF
E11: Unit Area: | H11: ='Systems Summary'!I19 -> NA | I11: SF
E12: Garage Area: | H12: ='Systems Summary'!I20 -> NA | I12: SF
B14: SPEC | G14: UNIT | H14: TOTAL | I14: COST
B15: SECT | D15: DESCRIPTION | E15: QUANT | F15: UNIT | G15: COST | H15: COST | I15: PER SF
B17: 01000 | D17: Temporary Construction | H17: ='Garage Detail'!H27 -> 0
B18: 02000 | D18: Site Work | H18: ='Garage Detail'!H65 -> 0
B19: 03000 | D19: Concrete | H19: ='Garage Detail'!H79 -> 0
B20: 04000 | D20: Masonry | H20: ='Garage Detail'!H89 -> 0
B21: 05000 | D21: Steel | H21: ='Garage Detail'!H101 -> 0
B22: 06000 | D22: Wood / Plastics | H22: ='Garage Detail'!H114 -> 0
B23: 07000 | D23: Thermal / Moisture Protection | H23: ='Garage Detail'!H131 -> 0
B24: 08000 | D24: Doors / Glass | H24: ='Garage Detail'!H141 -> 0
B25: 09000 | D25: Finishes | H25: ='Garage Detail'!H178 -> 0
B26: 10000 | D26: Specialties | H26: ='Garage Detail'!H188 -> 0
B27: 11000 | D27: Equipment | H27: ='Garage Detail'!H198 -> 0
B28: 12000 | D28: Furnishings | H28: ='Garage Detail'!H207 -> 0
B29: 13000 | D29: Special Construction | H29: ='Garage Detail'!H216 -> 0
B30: 14000 | D30: Conveying Systems | H30: ='Garage Detail'!H227 -> 0
B31: 15000 | D31: Mechanical | H31: ='Garage Detail'!H241 -> 0
B32: 16000 | D32: Electrical | H32: ='Garage Detail'!H256 -> 0
D35: Subtotal | H35: =SUM(H16:H33) -> 0
D37: General Conditions
D38: Builders Risk Insurance
D39: General Liability Insurance
D40: Bond
D41: Overhead
D42: Contractor's Fee
D45: Subtotal | H45: =SUM(H34:H43) -> 0
D47: Contractor's Contingency
D50: GARAGE TOTAL COST | H50: =SUM(H44:H48) -> 0

Sheet Garage Detail
A1: Project: | D1: ='Systems Summary'!D7 -> 356 S Daniel Way, San Jose, CA 95128 | E1: Project Type: | H1: ='Systems Summary'!I7 -> TI
A2: Location: | D2: ='Systems Summary'!D8 -> Close to Santana Row | E2: Structure Type: | H2: ='Systems Summary'!I8 -> Tilt Up
E3: No. Stories Below Grade: | H3: ='Systems Summary'!I9 -> NA
E4: No. Stories Above Grade: | H4: ='Systems Summary'!I10 -> 1
A5: Architect: | D5: ='Systems Summary'!D12 -> N/A | E5: No. of Units: | H5: ='Systems Summary'!I11 -> 2
E6: No. of Bathrooms: | H6: ='Systems Summary'!I12 -> 2
E7: Off-Site Area: | H7: ='Systems Summary'!I15 -> 0 | I7: SF
E8: Site Area: | H8: ='Systems Summary'!I16 -> 8720 | I8: SF
E9: ='Systems Summary'!F17 -> Lease Space/TI Area: | H9: ='Systems Summary'!I17 -> 8720 | I9: SF
E10: Common Area: | H10: ='Systems Summary'!I18 -> NA | I10: SF
E11: Unit Area: | H11: ='Systems Summary'!I19 -> NA | I11: SF
E12: Garage Area: | H12: ='Systems Summary'!I20 -> NA | I12: SF
B14: SPEC | G14: UNIT | H14: TOTAL | I14: COST
B15: SECT | D15: DESCRIPTION | E15: QUANT | F15: UNIT | G15: COST | H15: COST | I15: PER SF
B17: 01000 | D17: TEMPORARY CONSTRUCTION
B18: 01100 | D18: Scaffold | F18: SF | H18: =E18*G18 -> 0
B19: 01150 | D19: Temporary roads | F19: SF | H19: =E19*G19 -> 0
B20: 01200 | D20: Barricades | F20: EA | G20: 65 | H20: =E20*G20 -> 0
B21: 01250 | D21: Traffic control | F21: LS | G21: 4000 | H21: =E21*G21 -> 0
B22: 01260 | D22: Flagman | F22: LS | G22: 1200 | H22: =E22*G22 -> 0
B23: 01270 | D23: Safety rails | F23: LF | H23: =E23*G23 -> 0
D27: Temporary Construction Totals | H27: =SUM(H17:H25) -> 0 | I27: =H27/H9 -> 0
B30: 02000 | D30: SITE WORK
B31: 02050 | D31: Mobilizations | F31: LS | G31: 5000 | H31: =E31*G31 -> 0
B32: 02100 | D32: Clear and grub | F32: SF | H32: =E32*G32 -> 0
B33: 02105 | D33: Protect (e) trees | F33: EA | H33: =E33*G33 -> 0
B34: 02150 | D34: Demolition | F34: SF | H34: =E34*G34 -> 0
B35: 02175 | D35: Dewatering | F35: SF | H35: =E35*G35 -> 0
B36: 02550 | D36: Site Utilities:
D37: Sanitary Sewer | F37: LF | H37: =E37*G37 -> 0
D38: Storm Drain | F38: LF | H38: =E38*G38 -> 0
D39: - 18" RCP | F39: LF | H39: =E39*G39 -> 0
D40: - 15" RCP | F40: LF | H40: =E40*G40 -> 0
D41: - 12" RCP | F41: LF | H41: =E41*G41 -> 0
D42: - 10" RCP | F42: LF | H42: =E42*G42 -> 0
D43: - 8" RCP | F43: LF | H43: =E43*G43 -> 0
D44: - 6" RCP | F44: LF | H44: =E44*G44 -> 0
D45: - Tie to (e) manhole | F45: LS | H45: =E45*G45 -> 0
D46: - Catch basins | F46: EA | H46: =E46*G46 -> 0
D47: - Curb inlets | F47: EA | H47: =E47*G47 -> 0
...

Sheet Takeoffs
A2: SPEC
A3: DIV | B3: NO. | C3: DESCRIPTION | E3: QUANTITY | F3: UNITS | G3: REMARKS
A5: 00000 | C5: AREA CALCULATIONS
C6: Site Area | F6: SF
C7: Garage Common Area | F7: SF
C8: First Floor Common Area | F8: SF | G8: Say 1,000 SF
C9: Second Floor Common Area | F9: SF | G9: Say 1,000 SF
C10: Third Floor Common Area | F10: SF | G10: Say 1,000 SF
C11: Fourth Floor Common Area | F11: SF
C12: Total Common Area | F12: SF
C14: First Floor Net Area | F14: SF
C15: Second Floor Unit Net Area | F15: SF
C16: Third Floor Unit Net Area | F16: SF
C17: Fourth Floor Unit Net Area | F17: SF
C18: Total Unit Area | F18: SF
C20: LANDSCAPING
C21: Landscaping and irrigation area | F21: SF
C23: SPREAD FOOTINGS
C24: PIP Column Footings @ Garage | F24: CY
C25: Perimeter Building Footings | F25: CY
C26: Interior Footings @ CMU Walls | F26: CY
C28: SUSPENDED 1st FLOOR CONCRETE DECK
C29: Assume 10" suspended slab
